rm: cannot remove ‘full_chlL_BLAST_taxonomy.txt’: No such file or directory
Traceback (most recent call last):
  File "./../full_taxonomy.py", line 108, in <module>
    main()
  File "./../full_taxonomy.py", line 104, in main
    print(taxonomy(input()))
  File "./../full_taxonomy.py", line 62, in taxonomy
    handle = Entrez.efetch(db="taxonomy", id=taxon_id)
  File "/usr/local/packages/anaconda3/lib/python3.7/site-packages/Bio/Entrez/__init__.py", line 184, in efetch
    return _open(cgi, variables, post=post)
  File "/usr/local/packages/anaconda3/lib/python3.7/site-packages/Bio/Entrez/__init__.py", line 545, in _open
    raise exception
  File "/usr/local/packages/anaconda3/lib/python3.7/site-packages/Bio/Entrez/__init__.py", line 543, in _open
    handle = _urlopen(cgi)
  File "/usr/local/packages/anaconda3/lib/python3.7/urllib/request.py", line 222, in urlopen
    return opener.open(url, data, timeout)
  File "/usr/local/packages/anaconda3/lib/python3.7/urllib/request.py", line 531, in open
    response = meth(req, response)
  File "/usr/local/packages/anaconda3/lib/python3.7/urllib/request.py", line 641, in http_response
    'http', request, response, code, msg, hdrs)
  File "/usr/local/packages/anaconda3/lib/python3.7/urllib/request.py", line 569, in error
    return self._call_chain(*args)
  File "/usr/local/packages/anaconda3/lib/python3.7/urllib/request.py", line 503, in _call_chain
    result = func(*args)
  File "/usr/local/packages/anaconda3/lib/python3.7/urllib/request.py", line 649, in http_error_default
    raise HTTPError(req.full_url, code, msg, hdrs, fp)
urllib.error.HTTPError: HTTP Error 429: Too Many Requests
Traceback (most recent call last):
  File "./../full_taxonomy.py", line 108, in <module>
    main()
  File "./../full_taxonomy.py", line 104, in main
    print(taxonomy(input()))
  File "./../full_taxonomy.py", line 62, in taxonomy
    handle = Entrez.efetch(db="taxonomy", id=taxon_id)
  File "/usr/local/packages/anaconda3/lib/python3.7/site-packages/Bio/Entrez/__init__.py", line 184, in efetch
    return _open(cgi, variables, post=post)
  File "/usr/local/packages/anaconda3/lib/python3.7/site-packages/Bio/Entrez/__init__.py", line 545, in _open
    raise exception
  File "/usr/local/packages/anaconda3/lib/python3.7/site-packages/Bio/Entrez/__init__.py", line 543, in _open
    handle = _urlopen(cgi)
  File "/usr/local/packages/anaconda3/lib/python3.7/urllib/request.py", line 222, in urlopen
    return opener.open(url, data, timeout)
  File "/usr/local/packages/anaconda3/lib/python3.7/urllib/request.py", line 531, in open
    response = meth(req, response)
  File "/usr/local/packages/anaconda3/lib/python3.7/urllib/request.py", line 641, in http_response
    'http', request, response, code, msg, hdrs)
  File "/usr/local/packages/anaconda3/lib/python3.7/urllib/request.py", line 569, in error
    return self._call_chain(*args)
  File "/usr/local/packages/anaconda3/lib/python3.7/urllib/request.py", line 503, in _call_chain
    result = func(*args)
  File "/usr/local/packages/anaconda3/lib/python3.7/urllib/request.py", line 649, in http_error_default
    raise HTTPError(req.full_url, code, msg, hdrs, fp)
urllib.error.HTTPError: HTTP Error 429: Too Many Requests
Traceback (most recent call last):
  File "./../full_taxonomy.py", line 108, in <module>
    main()
  File "./../full_taxonomy.py", line 104, in main
    print(taxonomy(input()))
  File "./../full_taxonomy.py", line 62, in taxonomy
    handle = Entrez.efetch(db="taxonomy", id=taxon_id)
  File "/usr/local/packages/anaconda3/lib/python3.7/site-packages/Bio/Entrez/__init__.py", line 184, in efetch
    return _open(cgi, variables, post=post)
  File "/usr/local/packages/anaconda3/lib/python3.7/site-packages/Bio/Entrez/__init__.py", line 545, in _open
    raise exception
  File "/usr/local/packages/anaconda3/lib/python3.7/site-packages/Bio/Entrez/__init__.py", line 543, in _open
    handle = _urlopen(cgi)
  File "/usr/local/packages/anaconda3/lib/python3.7/urllib/request.py", line 222, in urlopen
    return opener.open(url, data, timeout)
  File "/usr/local/packages/anaconda3/lib/python3.7/urllib/request.py", line 531, in open
    response = meth(req, response)
  File "/usr/local/packages/anaconda3/lib/python3.7/urllib/request.py", line 641, in http_response
    'http', request, response, code, msg, hdrs)
  File "/usr/local/packages/anaconda3/lib/python3.7/urllib/request.py", line 569, in error
    return self._call_chain(*args)
  File "/usr/local/packages/anaconda3/lib/python3.7/urllib/request.py", line 503, in _call_chain
    result = func(*args)
  File "/usr/local/packages/anaconda3/lib/python3.7/urllib/request.py", line 649, in http_error_default
    raise HTTPError(req.full_url, code, msg, hdrs, fp)
urllib.error.HTTPError: HTTP Error 429: Too Many Requests
Traceback (most recent call last):
  File "./../full_taxonomy.py", line 108, in <module>
    main()
  File "./../full_taxonomy.py", line 104, in main
    print(taxonomy(input()))
  File "./../full_taxonomy.py", line 62, in taxonomy
    handle = Entrez.efetch(db="taxonomy", id=taxon_id)
  File "/usr/local/packages/anaconda3/lib/python3.7/site-packages/Bio/Entrez/__init__.py", line 184, in efetch
    return _open(cgi, variables, post=post)
  File "/usr/local/packages/anaconda3/lib/python3.7/site-packages/Bio/Entrez/__init__.py", line 545, in _open
    raise exception
  File "/usr/local/packages/anaconda3/lib/python3.7/site-packages/Bio/Entrez/__init__.py", line 543, in _open
    handle = _urlopen(cgi)
  File "/usr/local/packages/anaconda3/lib/python3.7/urllib/request.py", line 222, in urlopen
    return opener.open(url, data, timeout)
  File "/usr/local/packages/anaconda3/lib/python3.7/urllib/request.py", line 531, in open
    response = meth(req, response)
  File "/usr/local/packages/anaconda3/lib/python3.7/urllib/request.py", line 641, in http_response
    'http', request, response, code, msg, hdrs)
  File "/usr/local/packages/anaconda3/lib/python3.7/urllib/request.py", line 569, in error
    return self._call_chain(*args)
  File "/usr/local/packages/anaconda3/lib/python3.7/urllib/request.py", line 503, in _call_chain
    result = func(*args)
  File "/usr/local/packages/anaconda3/lib/python3.7/urllib/request.py", line 649, in http_error_default
    raise HTTPError(req.full_url, code, msg, hdrs, fp)
urllib.error.HTTPError: HTTP Error 429: Too Many Requests
Traceback (most recent call last):
  File "./../full_taxonomy.py", line 108, in <module>
    main()
  File "./../full_taxonomy.py", line 104, in main
    print(taxonomy(input()))
  File "./../full_taxonomy.py", line 62, in taxonomy
    handle = Entrez.efetch(db="taxonomy", id=taxon_id)
  File "/usr/local/packages/anaconda3/lib/python3.7/site-packages/Bio/Entrez/__init__.py", line 184, in efetch
    return _open(cgi, variables, post=post)
  File "/usr/local/packages/anaconda3/lib/python3.7/site-packages/Bio/Entrez/__init__.py", line 545, in _open
    raise exception
  File "/usr/local/packages/anaconda3/lib/python3.7/site-packages/Bio/Entrez/__init__.py", line 543, in _open
    handle = _urlopen(cgi)
  File "/usr/local/packages/anaconda3/lib/python3.7/urllib/request.py", line 222, in urlopen
    return opener.open(url, data, timeout)
  File "/usr/local/packages/anaconda3/lib/python3.7/urllib/request.py", line 531, in open
    response = meth(req, response)
  File "/usr/local/packages/anaconda3/lib/python3.7/urllib/request.py", line 641, in http_response
    'http', request, response, code, msg, hdrs)
  File "/usr/local/packages/anaconda3/lib/python3.7/urllib/request.py", line 569, in error
    return self._call_chain(*args)
  File "/usr/local/packages/anaconda3/lib/python3.7/urllib/request.py", line 503, in _call_chain
    result = func(*args)
  File "/usr/local/packages/anaconda3/lib/python3.7/urllib/request.py", line 649, in http_error_default
    raise HTTPError(req.full_url, code, msg, hdrs, fp)
urllib.error.HTTPError: HTTP Error 429: Too Many Requests
Traceback (most recent call last):
  File "./../full_taxonomy.py", line 108, in <module>
    main()
  File "./../full_taxonomy.py", line 104, in main
    print(taxonomy(input()))
  File "./../full_taxonomy.py", line 62, in taxonomy
    handle = Entrez.efetch(db="taxonomy", id=taxon_id)
  File "/usr/local/packages/anaconda3/lib/python3.7/site-packages/Bio/Entrez/__init__.py", line 184, in efetch
    return _open(cgi, variables, post=post)
  File "/usr/local/packages/anaconda3/lib/python3.7/site-packages/Bio/Entrez/__init__.py", line 545, in _open
    raise exception
  File "/usr/local/packages/anaconda3/lib/python3.7/site-packages/Bio/Entrez/__init__.py", line 543, in _open
    handle = _urlopen(cgi)
  File "/usr/local/packages/anaconda3/lib/python3.7/urllib/request.py", line 222, in urlopen
    return opener.open(url, data, timeout)
  File "/usr/local/packages/anaconda3/lib/python3.7/urllib/request.py", line 531, in open
    response = meth(req, response)
  File "/usr/local/packages/anaconda3/lib/python3.7/urllib/request.py", line 641, in http_response
    'http', request, response, code, msg, hdrs)
  File "/usr/local/packages/anaconda3/lib/python3.7/urllib/request.py", line 569, in error
    return self._call_chain(*args)
  File "/usr/local/packages/anaconda3/lib/python3.7/urllib/request.py", line 503, in _call_chain
    result = func(*args)
  File "/usr/local/packages/anaconda3/lib/python3.7/urllib/request.py", line 649, in http_error_default
    raise HTTPError(req.full_url, code, msg, hdrs, fp)
urllib.error.HTTPError: HTTP Error 429: Too Many Requests
